<?xml version="1.0" ?>
<robot name="robot">
  <link name='Frame'>
      <pose>0 0 0 0 -0 0</pose>
      <visual>
        <pose>0 0 0.04826 0 -0 3.14159</pose>
        <geometry>
          <mesh>
            <scale>1 1 1</scale>
            <uri>../meshes/Frame_Detailed.STL</uri>
          </mesh>
        </geometry>
      </visual>
      <collision>
        <pose>0 0 0.04826 0 -0 0</pose>
        <geometry>
          <mesh>
            <uri>../meshes/Frame.STL</uri>
            <scale>1 1 1</scale>
          </mesh>
        </geometry>
      </collision>
  </link>
    <link name='BL_Wheel'>
      <pose>-0.012938 0.1062 0.099568 -1.5707963267949 0 -3.14159</pose>
      <visual>
        <pose>0 0 0 0 -0 0</pose>
        <geometry>
          <mesh>
            <scale>1 1 1</scale>
            <uri>../meshes/Wheel_Detailed.STL</uri>
          </mesh>
        </geometry>
      </visual>
      <collision>
        <pose>0.03 0 0 0 1.5707963267949 0</pose>
        <geometry>
          <cylinder>
            <radius>0.098894</radius>
            <length>0.054193</length>
          </cylinder>
        </geometry>
      </collision>
    </link>
    <link name='BR_Wheel'>
      <pose>0.67333 0.1062 0.099568 1.5707963267949 0 0</pose>
      <visual>
        <pose>0 0 0 0 -0 0</pose>
        <geometry>
          <mesh>
            <scale>1 1 1</scale>
            <uri>../meshes/Wheel_Detailed.STL</uri>
          </mesh>
        </geometry>
      </visual>
      <collision>
        <pose>0.02 0 0 0 1.5707963267949 0</pose>
        <geometry>
          <cylinder>
            <radius>0.098894</radius>
            <length>0.054193</length>
          </cylinder>
        </geometry>
      </collision>
    </link>
    <link name='FL_Wheel'>
      <pose>-0.012938 0.8082 0.099568 -1.5707963267949 0 -3.14159</pose>
      <visual>
        <pose>0 0 0 0 -0 0</pose>
        <geometry>
          <mesh>
            <scale>1 1 1</scale>
            <uri>../meshes/Wheel_Detailed.STL</uri>
          </mesh>
        </geometry>
      </visual>
      <collision>
        <pose>0.02 0 0 0 1.5707963267949 0</pose>
        <geometry>
          <cylinder>
            <radius>0.098894</radius>
            <length>0.054193</length>
          </cylinder>
        </geometry>
      </collision>
    </link>
    <link name='FR_Wheel'>
      <pose>0.67333 0.8082 0.099568 1.5707963267949 0 0</pose>
      <visual>
        <pose>0 0 0 0 -0 0</pose>
        <geometry>
          <mesh>
            <scale>1 1 1</scale>
            <uri>../meshes/Wheel_Detailed.STL</uri>
          </mesh>
        </geometry>
      </visual>
      <collision>
        <pose>0.02 0 0 0 1.5707963267949 0</pose>
        <geometry>
          <cylinder>
            <radius>0.098894</radius>
            <length>0.054193</length>
          </cylinder>
        </geometry>
      </collision>
    </link>
    <joint name='BL_Axel' type='revolute'>
      <parent>Frame</parent>
      <child>BL_Wheel</child>
      <pose>0 -0 -0 0 0 -3.14159</pose>
      <axis>
        <xyz>0 0 0</xyz>
        <limit>
          <lower>-1e+16</lower>
          <upper>1e+16</upper>
          <effort>-1</effort>
          <velocity>-1</velocity>
        </limit>
        <dynamics>
          <spring_reference>0</spring_reference>
          <spring_stiffness>0</spring_stiffness>
          <damping>0</damping>
          <friction>0</friction>
        </dynamics>
      </axis>
      <physics>
        <ode>
          <limit>
            <cfm>0</cfm>
            <erp>0.2</erp>
          </limit>
          <suspension>
            <cfm>0</cfm>
            <erp>0.2</erp>
          </suspension>
        </ode>
      </physics>
    </joint>
    <joint name='BR_Axel' type='revolute'>
      <parent>Frame</parent>
      <child>BR_Wheel</child>
      <pose>0 -0 -0 0 -0 0</pose>
      <axis>
        <xyz>0 0 0</xyz>
        <limit>
          <lower>-1e+16</lower>
          <upper>1e+16</upper>
          <effort>-1</effort>
          <velocity>-1</velocity>
        </limit>
        <dynamics>
          <spring_reference>0</spring_reference>
          <spring_stiffness>0</spring_stiffness>
          <damping>0</damping>
          <friction>0</friction>
        </dynamics>
      </axis>
      <physics>
        <ode>
          <limit>
            <cfm>0</cfm>
            <erp>0.2</erp>
          </limit>
          <suspension>
            <cfm>0</cfm>
            <erp>0.2</erp>
          </suspension>
        </ode>
      </physics>
    </joint>
    <joint name='FL_Axel' type='revolute'>
      <parent>Frame</parent>
      <child>FL_Wheel</child>
      <pose>0 0 0 0 0 -3.14159</pose>
      <axis>
        <xyz>0 0 0</xyz>
        <limit>
          <lower>-1e+16</lower>
          <upper>1e+16</upper>
          <effort>-1</effort>
          <velocity>-1</velocity>
        </limit>
        <dynamics>
          <spring_reference>0</spring_reference>
          <spring_stiffness>0</spring_stiffness>
          <damping>0</damping>
          <friction>0</friction>
        </dynamics>
      </axis>
      <physics>
        <ode>
          <limit>
            <cfm>0</cfm>
            <erp>0.2</erp>
          </limit>
          <suspension>
            <cfm>0</cfm>
            <erp>0.2</erp>
          </suspension>
        </ode>
      </physics>
    </joint>
    <joint name='FR_Axel' type='revolute'>
      <parent>Frame</parent>
      <child>FR_Wheel</child>
      <pose>0 -0 -0 0 -0 0</pose>
      <axis>
        <xyz>0 0 0</xyz>
        <limit>
          <lower>-1e+16</lower>
          <upper>1e+16</upper>
          <effort>-1</effort>
          <velocity>-1</velocity>
        </limit>
        <dynamics>
          <spring_reference>0</spring_reference>
          <spring_stiffness>0</spring_stiffness>
          <damping>0</damping>
          <friction>0</friction>
        </dynamics>
      </axis>
      <physics>
        <ode>
          <limit>
            <cfm>0</cfm>
            <erp>0.2</erp>
          </limit>
          <suspension>
            <cfm>0</cfm>
            <erp>0.2</erp>
          </suspension>
        </ode>
      </physics>
      </joint>
</robot>
